[34m[1mwandb[39m[22m:   3 of 3 files downloaded.
/Users/keanl/miniforge3/lib/python3.10/random.py:370: DeprecationWarning: non-integer arguments to randrange() have been deprecated since Python 3.10 and will be removed in a subsequent version
  return self.randrange(a, b+1)
Traceback (most recent call last):
  File "/Users/keanl/Desktop/Computer_Science/Comp_775/project/Comp775Project/train_segment_afa.py", line 42, in <module>
    main()
  File "/Users/keanl/Desktop/Computer_Science/Comp_775/project/Comp775Project/train_segment_afa.py", line 38, in main
    model.load_weights(os.path.join(unet_artifact_dir))
  File "/Users/keanl/miniforge3/lib/python3.10/site-packages/keras/utils/traceback_utils.py", line 70, in error_handler
    raise e.with_traceback(filtered_tb) from None
  File "/Users/keanl/miniforge3/lib/python3.10/site-packages/h5py/_hl/files.py", line 507, in __init__
    fid = make_fid(name, mode, userblock_size, fapl, fcpl, swmr=swmr)
  File "/Users/keanl/miniforge3/lib/python3.10/site-packages/h5py/_hl/files.py", line 220, in make_fid
    fid = h5f.open(name, flags, fapl=fapl)
  File "h5py/_objects.pyx", line 54, in h5py._objects.with_phil.wrapper
  File "h5py/_objects.pyx", line 55, in h5py._objects.with_phil.wrapper
  File "h5py/h5f.pyx", line 106, in h5py.h5f.open
IsADirectoryError: [Errno 21] Unable to open file (file read failed: time = Fri Dec  2 22:33:25 2022
, filename = '/Users/keanl/Desktop/Computer_Science/Comp_775/project/Comp775Project/artifacts/oxford_pet_unet_classifier:v18', file descriptor = 12, errno = 21, error message = 'Is a directory', buf = 0x16f280d20, total read size = 8, bytes this sub-read = 8, bytes actually read = 18446744073709551615, offset = 0)
Traceback (most recent call last):
  File "/Users/keanl/Desktop/Computer_Science/Comp_775/project/Comp775Project/train_segment_afa.py", line 42, in <module>
    main()
  File "/Users/keanl/Desktop/Computer_Science/Comp_775/project/Comp775Project/train_segment_afa.py", line 38, in main
    model.load_weights(os.path.join(unet_artifact_dir))
  File "/Users/keanl/miniforge3/lib/python3.10/site-packages/keras/utils/traceback_utils.py", line 70, in error_handler
    raise e.with_traceback(filtered_tb) from None
  File "/Users/keanl/miniforge3/lib/python3.10/site-packages/h5py/_hl/files.py", line 507, in __init__
    fid = make_fid(name, mode, userblock_size, fapl, fcpl, swmr=swmr)
  File "/Users/keanl/miniforge3/lib/python3.10/site-packages/h5py/_hl/files.py", line 220, in make_fid
    fid = h5f.open(name, flags, fapl=fapl)
  File "h5py/_objects.pyx", line 54, in h5py._objects.with_phil.wrapper
  File "h5py/_objects.pyx", line 55, in h5py._objects.with_phil.wrapper
  File "h5py/h5f.pyx", line 106, in h5py.h5f.open
IsADirectoryError: [Errno 21] Unable to open file (file read failed: time = Fri Dec  2 22:33:25 2022
, filename = '/Users/keanl/Desktop/Computer_Science/Comp_775/project/Comp775Project/artifacts/oxford_pet_unet_classifier:v18', file descriptor = 12, errno = 21, error message = 'Is a directory', buf = 0x16f280d20, total read size = 8, bytes this sub-read = 8, bytes actually read = 18446744073709551615, offset = 0)